

简单的尝试失败

```go
// 我们先写一个最简单的2个任务，第一个任务执行5s, 第二个任务执行10s, 整体任务超时时间设置为7秒，
// 我们希望得到的结果是整体任务执行7s，超时就退出了
func taskWithTimeout() error {
	eg := errgroup.Group{}

	// 第一个任务执行 5s
	eg.Go(func() error {
		for i := 0; i < 5; i++ {
			time.Sleep(1 * time.Second)
			fmt.Println("任务 1 执行中...")
		}
		fmt.Println("任务 1 执行完成")
		return nil
	})

	// 第二个任务执行 10s
	eg.Go(func() error {
		for i := 0; i < 10; i++ {
			time.Sleep(1 * time.Second)
			fmt.Println("任务 2 执行中...")
		}
		fmt.Println("任务 2 执行完成")
		return nil
	})

	if err := eg.Wait(); err != nil {
		return fmt.Errorf("过了超时时间 %s", err)
	}
	return nil
}

//任务 1 执行中...
//任务 2 执行中...
//任务 2 执行中...
//任务 1 执行中...
//任务 2 执行中...
//任务 1 执行中...
//任务 1 执行中...
//任务 2 执行中...
//任务 1 执行中...
//任务 1 执行完成
//任务 2 执行中...
//任务 2 执行中...
//任务 2 执行中...
//任务 2 执行中...
//任务 2 执行中...
//任务 2 执行中...
//任务 2 执行完成
//所有任务在超时前完成
func main() {

	if err := taskWithTimeout(); err != nil {
		fmt.Println(err)
	} else {
		fmt.Println("所有任务在超时前完成")
	}
}

```

我们加入了context.WithTimeout，发现并没有按照预期在7s停止，而且我们errgroup也是按照设想的context删除

```go

package main

import (
	"context"
	"fmt"
	"golang.org/x/sync/errgroup"
	"time"
)

// 我们先写一个最简单的2个任务，第一个任务执行5s, 第二个任务执行10s, 整体任务超时时间设置为7秒，
// 我们希望得到的结果是整体任务执行7s，超时就退出了
func taskWithTimeout() error {
	ctx, cancel := context.WithTimeout(context.Background(), 7*time.Second)
	defer cancel()

	eg, ctx := errgroup.WithContext(ctx)

	// 第一个任务执行 5s
	eg.Go(func() error {
		for i := 0; i < 5; i++ {
			time.Sleep(1 * time.Second)
			fmt.Println("任务 1 执行中...")
		}
		fmt.Println("任务 1 执行完成")
		return nil
	})

	// 第二个任务执行 10s
	eg.Go(func() error {
		for i := 0; i < 10; i++ {
			time.Sleep(1 * time.Second)
			fmt.Println("任务 2 执行中...")
		}
		fmt.Println("任务 2 执行完成")
		return nil
	})

	if err := eg.Wait(); err != nil {
		return fmt.Errorf("过了超时时间 %s", err)
	}
	return nil
}

// 任务 2 执行中...
//任务 1 执行中...
//任务 1 执行中...
//任务 2 执行中...
//任务 2 执行中...
//任务 1 执行中...
//任务 1 执行中...
//任务 2 执行中...
//任务 1 执行中...
//任务 1 执行完成
//任务 2 执行中...
//任务 2 执行中...
//任务 2 执行中...
//任务 2 执行中...
//任务 2 执行中...
//任务 2 执行中...
//任务 2 执行完成
//所有任务在超时前完成
func main() {

	if err := taskWithTimeout(); err != nil {
		fmt.Println(err)
	} else {
		fmt.Println("所有任务在超时前完成")
	}
}

```

我们发现返回的数据并没有像我们设想那样终止，errgroup会等待所有协程执行结束，那么如果我加一个协程来监控如果超时那么报错会怎么样


```go

// 我们先写一个最简单的2个任务，第一个任务执行5s, 第二个任务执行10s, 整体任务超时时间设置为7秒，
// 我们希望得到的结果是整体任务执行7s，超时就退出了
func taskWithTimeout() error {
	ctx, cancel := context.WithTimeout(context.Background(), 7*time.Second)
	defer cancel()

	eg, ctx := errgroup.WithContext(ctx)

	// 第一个任务执行 5s
	eg.Go(func() error {
		for i := 0; i < 5; i++ {
			time.Sleep(1 * time.Second)
			fmt.Println("任务 1 执行中...")
		}
		fmt.Println("任务 1 执行完成")
		return nil
	})

	// 第二个任务执行 10s
	eg.Go(func() error {
		for i := 0; i < 10; i++ {
			time.Sleep(1 * time.Second)
			fmt.Println("任务 2 执行中...")
		}
		fmt.Println("任务 2 执行完成")
		return nil
	})

	// 第三个协程来接受报错，通知关闭
	eg.Go(func() error {
		<-ctx.Done()
		return ctx.Err()
	})

	if err := eg.Wait(); err != nil {
		return fmt.Errorf("过了超时时间 %s", err)
	}
	return nil
}

// 任务 2 执行中...
//任务 1 执行中...
//任务 2 执行中...
//任务 1 执行中...
//任务 1 执行中...
//任务 2 执行中...
//任务 2 执行中...
//任务 1 执行中...
//任务 1 执行中...
//任务 1 执行完成
//任务 2 执行中...
//任务 2 执行中...
//任务 2 执行中...
//任务 2 执行中...
//任务 2 执行中...
//任务 2 执行中...
//任务 2 执行完成
//过了超时时间 context deadline exceeded
func main() {

	if err := taskWithTimeout(); err != nil {
		fmt.Println(err)
	} else {
		fmt.Println("所有任务在超时前完成")
	}
}

```

我们发现有一些变化就是errGroup报错了，但是一个线程出错，他并没有关闭所有的线程，而是等所有的线程执行完成，
那么我们的改进思路是所有线程里面监听context是否报错，同时用select让每时每刻都被监控到
```go
package main

import (
	"context"
	"fmt"
	"golang.org/x/sync/errgroup"
	"time"
)

// 我们先写一个最简单的2个任务，第一个任务执行5s, 第二个任务执行10s, 整体任务超时时间设置为7秒，
// 我们希望得到的结果是整体任务执行7s，超时就退出了
func taskWithTimeout() error {
	ctx, cancel := context.WithTimeout(context.Background(), 7*time.Second)
	defer cancel()

	eg, ctx := errgroup.WithContext(ctx)

	// 第一个任务执行 5s
	eg.Go(func() error {
		for i := 0; i < 5; i++ {
			time.Sleep(1 * time.Second)
			fmt.Println("任务 1 执行中...")
		}
		fmt.Println("任务 1 执行完成")
		return nil
	})

	// 第二个任务执行 10s
	eg.Go(func() error {
		select {
		case <-ctx.Done():
			return ctx.Err()
		default:
			for i := 0; i < 10; i++ {
				time.Sleep(1 * time.Second)
				fmt.Println("任务 2 执行中...")
			}
			fmt.Println("任务 2 执行完成")
		}
		return nil
	})

	// 第三个协程来接受报错，通知关闭
	eg.Go(func() error {
		<-ctx.Done()
		return ctx.Err()
	})

	if err := eg.Wait(); err != nil {
		return fmt.Errorf("过了超时时间 %s", err)
	}
	return nil
}

// 任务 2 执行中...
//任务 1 执行中...
//任务 1 执行中...
//任务 2 执行中...
//任务 2 执行中...
//任务 1 执行中...
//任务 1 执行中...
//任务 2 执行中...
//任务 2 执行中...
//任务 1 执行中...
//任务 1 执行完成
//任务 2 执行中...
//任务 2 执行中...
//任务 2 执行中...
//任务 2 执行中...
//任务 2 执行中...
//任务 2 执行完成
//过了超时时间 context deadline exceeded
func main() {

	if err := taskWithTimeout(); err != nil {
		fmt.Println(err)
	} else {
		fmt.Println("所有任务在超时前完成")
	}
}

```

我们发现并没有按照我们预期，想了像我尝试下面的写法，结果还是不能复合预期
```go
// 第二个任务执行 10s
	eg.Go(func() error {
		for {
			select {
			case <-ctx.Done():
				return ctx.Err()
			default:
				for i := 0; i < 10; i++ {
					time.Sleep(1 * time.Second)
					fmt.Println("任务 2 执行中...")
				}
				fmt.Println("任务 2 执行完成")
			}
		}
		return nil
	})
```

这样写的问题在于，for 循环会不断重试任务，而每次执行完 10 秒的 for i := 0; i < 10 循环后，它会再次进入外层的 for 循环。这会导致任务 2 永远不会退出，即使 ctx.Done() 已触发，仍然会继续运行直到整个程序终止。

修复方法，可以直接移除外层的无限循环 for，改为单次任务检查，确保任务 2 在第一次执行完 10 秒后检查 ctx.Done()，然后及时退出：

```go
// 第二个任务执行 10s
	eg.Go(func() error {
		for i := 0; i < 10; i++ {
			select {
			case <-ctx.Done():
				return ctx.Err()
			default:
				time.Sleep(1 * time.Second)
				fmt.Println("任务 2 执行中...")
			}
		}
		fmt.Println("任务 2 执行完成")
		return nil
	})

```