# 记录一次调第三方接口轮巡学到的内容

### 清理描述

状况描述，我们需要扫描27000条数据，开10个线程线程轮巡，平均一小时能扫描1000条，这样的话，我等27个小时就可以完成所有的东西。



但奇怪的是，每次执行一小时的时候，程序就不再执行下去了，我看着程序一直在运行，但是没有结果返回，然后我也加入了超时限制，似乎并没有生效，这里贴一下到这一步的代码。


```go
var (
	summaryTaskCounts = 100             // 总任务两是100
	concurrencyCount  = 10              // 并发数是10
	timeout           = 3 * time.Minute // 超时时间是3分钟
)

func pullingLogic(taskId int) error {
	for {
		result := getTaskResult(taskId)
		if strings.Contains(result, "任务未完成") {
			time.Sleep(5 * time.Second)
			continue
		}
		break
	}
	fmt.Printf("任务ID %d 完成\n", taskId)
	return nil
}

func getTaskResult(taskId int) string {
	rand.Seed(time.Now().UnixNano() + int64(taskId))
	if rand.Intn(2) == 0 {
		return "任务未完成"
	}

	// 这里是模拟第三方接口偶尔会出现的一个接口无论如何都执行不完，即使超时24小时
	if taskId == 22 || taskId == 56 || taskId == 77 {
		return "任务未完成"
	}
	return "任务完成"
}

func main() {
	// 总任务循环
	for i := 0; i < summaryTaskCounts; i += concurrencyCount {
		// 并发执行拉去
		// 每次重试都创建一个带有超时的 context
		ctx, cancel := context.WithTimeout(context.Background(), timeout)
		defer cancel()

		// 使用 errorgroup 来管理这次重试的协程
		eg, ctx := errgroup.WithContext(ctx)
		for j := 0; j < concurrencyCount; j++ {
			taskId := i + j // 捕获循环变量
			eg.Go(func() error {
				return pullingLogic(taskId)
			})
		}
		if err := eg.Wait(); err != nil {
			fmt.Printf("并发执行出错: %v \n", err)
		}
	}
	fmt.Printf("所有任务执行完成")
}
```


似乎卡在这里了，我一下子没有思路了，问领导，领导让我先理解清楚errgroup什么时候会终止的机制，于是我开始写代码



然后先加入日志的时间信息，记录每一个地方的执行时间，为了验证我对errgroup超时理解，我写了如下代码，发现我一开始理解的errgroup出现一个出错会终止的现象是理解错误的。

```go
// 我们先写一个最简单的2个任务，第一个任务执行5s, 第二个任务执行10s, 整体任务超时时间设置为7秒，
// 我们希望得到的结果是整体任务执行7s，超时就退出了
func taskWithTimeout() error {
	eg := errgroup.Group{}

	// 第一个任务执行 5s
	eg.Go(func() error {
		for i := 0; i < 5; i++ {
			time.Sleep(1 * time.Second)
			fmt.Println("任务 1 执行中...")
		}
		fmt.Println("任务 1 执行完成")
		return nil
	})

	// 第二个任务执行 10s
	eg.Go(func() error {
		for i := 0; i < 10; i++ {
			time.Sleep(1 * time.Second)
			fmt.Println("任务 2 执行中...")
		}
		fmt.Println("任务 2 执行完成")
		return nil
	})

	if err := eg.Wait(); err != nil {
		return fmt.Errorf("过了超时时间 %s", err)
	}
	return nil
}

// 任务 1 执行中...
// 任务 2 执行中...
// 任务 2 执行中...
// 任务 1 执行中...
// 任务 2 执行中...
// 任务 1 执行中...
// 任务 1 执行中...
// 任务 2 执行中...
// 任务 1 执行中...
// 任务 1 执行完成
// 任务 2 执行中...
// 任务 2 执行中...
// 任务 2 执行中...
// 任务 2 执行中...
// 任务 2 执行中...
// 任务 2 执行中...
// 任务 2 执行完成
// 所有任务在超时前完成
func main() {

	if err := taskWithTimeout(); err != nil {
		fmt.Println(err)
	} else {
		fmt.Println("所有任务在超时前完成")
	}
}

```

通过上面的代码，发现通过context控制超时会让errgroup受到报错信息，但是原来的那个线程还是会一直执行下去，这是问题所在，于是调整到下面的代码


```go
// 我们先写一个最简单的2个任务，第一个任务执行5s, 第二个任务执行10s, 整体任务超时时间设置为7秒，
// 我们希望得到的结果是整体任务执行7s，超时就退出了
func taskWithTimeout() error {
	ctx, cancel := context.WithTimeout(context.Background(), 7*time.Second)
	defer cancel()

	eg, ctx := errgroup.WithContext(ctx)

	// 第一个任务执行 5s
	eg.Go(func() error {
		for i := 0; i < 5; i++ {
			time.Sleep(1 * time.Second)
			fmt.Println("任务 1 执行中...")
		}
		fmt.Println("任务 1 执行完成")
		return nil
	})

	// 第二个任务执行 10s
	eg.Go(func() error {
		for i := 0; i < 10; i++ {
			select {
			case <-ctx.Done():
				return ctx.Err()
			default:
				time.Sleep(1 * time.Second)
				fmt.Println("任务 2 执行中...")
			}
		}
		fmt.Println("任务 2 执行完成")
		return nil
	})

	if err := eg.Wait(); err != nil {
		return fmt.Errorf("过了超时时间 %s", err)
	}
	return nil
}

// 任务 1 执行中...
// 任务 2 执行中...
// 任务 1 执行中...
// 任务 2 执行中...
// 任务 1 执行中...
// 任务 2 执行中...
// 任务 1 执行中...
// 任务 2 执行中...
// 任务 1 执行中...
// 任务 1 执行完成
// 任务 2 执行中...
// 任务 2 执行中...
// 任务 2 执行中...
// 过了超时时间 context deadline exceeded
func main() {

	if err := taskWithTimeout(); err != nil {
		fmt.Println(err)
	} else {
		fmt.Println("所有任务在超时前完成")
	}
}

```

说明，为了解决这个问题，需要在每一个errgroup的线程中受到context超时是就立即给errgroup返回报错，这样才能结束原来那个超时的线程，记得领导说errgroup并不是有一个报错就结束所有线程的运行，而是等到所有协程运行完成或报错才停止运行。


然后我就利用新的理解重新改造了代码如下，发现确实解决了问题

```go
var (
	summaryTaskCounts = 100             // 总任务两是100
	concurrencyCount  = 10              // 并发数是10
	timeout           = 3 * time.Minute // 超时时间是3分钟
)

func pullingLogic(ctx context.Context, taskId int) error {
	for {
		select {
		case <-ctx.Done():
			return ctx.Err()
		default:
			result := getTaskResult(taskId)
			if strings.Contains(result, "任务未完成") {
				time.Sleep(5 * time.Second)
				continue
			}
			fmt.Printf("任务ID %d 完成\n", taskId)
			return nil
		}
	}
}

func getTaskResult(taskId int) string {
	rand.Seed(time.Now().UnixNano() + int64(taskId))
	if rand.Intn(2) == 0 {
		return "任务未完成"
	}

	// 这里是模拟第三方接口偶尔会出现的一个接口无论如何都执行不完，即使超时24小时
	if taskId == 22 || taskId == 56 || taskId == 77 {
		return "任务未完成"
	}
	return "任务完成"
}

func main() {
	// 总任务循环
	for i := 0; i < summaryTaskCounts; i += concurrencyCount {
		// 并发执行拉去
		// 每次重试都创建一个带有超时的 context
		ctx, cancel := context.WithTimeout(context.Background(), timeout)
		defer cancel()

		// 使用 errorgroup 来管理这次重试的协程
		eg, ctx := errgroup.WithContext(ctx)
		for j := 0; j < concurrencyCount; j++ {
			taskId := i + j // 捕获循环变量
			eg.Go(func() error {
				return pullingLogic(ctx, taskId)
			})
		}
		if err := eg.Wait(); err != nil {
			fmt.Printf("并发执行出错: %v \n", err)
		}
	}
	fmt.Printf("所有任务执行完成")
}


```

通过以上学习，我理解了阻塞的概念，以及为什么每个errgroup协程如果在context.Done时没有处理，那么这个协程还是会继续执行下图，
特别是我上面的扫描逻辑，会阻塞的无法扫描完成全部的2万7千条数据。如果数据量小，比如只有3000条，那么多重启几次程序就可以了，
现在数据量这么多，我不可能每间隔1小时看一次执行状态然后知道27小时左右扫描2万7千条。

想到了是这样必须解决非常难的问题的机会，逼迫这我学习和解决这个问题，也学会利用代码为自己偷懒，提升效率